<?xml version="1.0" ?>
<!-- =================================================================================== -->
<!-- |    This document was autogenerated by xacro from /home/balaji/ro47007_mirte_ws/src/mirte-ros-packages/mirte_description/mirte_master_description/urdf/mirte_master.xacro | -->
<!-- |    EDITING THIS FILE BY HAND IS NOT RECOMMENDED                                 | -->
<!-- =================================================================================== -->
<robot name="mirte_master">
  <mujoco>
    <visual><global offwidth="1280" offheight="960"/></visual>
    <compiler meshdir="." balanceinertia="true" discardvisual="false" fusestatic="false"/>
  </mujoco>

  <material name="blue">
    <color rgba="0.203125 0.23828125 0.28515625 1.0"/>
  </material>
  <gazebo reference="base_link">
    <material>Gazebo/White</material>
    <gravity>true</gravity>
  </gazebo>
  <gazebo reference="wheel_front_left">
    <selfCollide>false</selfCollide>
    <gravity>true</gravity>
    <mu1>0.0</mu1>
    <mu2>0.0</mu2>
    <material>Gazebo/DarkGrey</material>
  </gazebo>
  <gazebo reference="wheel_rear_left">
    <selfCollide>false</selfCollide>
    <gravity>true</gravity>
    <mu1>0.0</mu1>
    <mu2>0.0</mu2>
    <material>Gazebo/DarkGrey</material>
  </gazebo>
  <gazebo reference="wheel_front_right">
    <selfCollide>false</selfCollide>
    <gravity>true</gravity>
    <mu1>0.0</mu1>
    <mu2>0.0</mu2>
    <material>Gazebo/DarkGrey</material>
  </gazebo>
  <gazebo reference="wheel_rear_right">
    <selfCollide>false</selfCollide>
    <gravity>true</gravity>
    <mu1>0.0</mu1>
    <mu2>0.0</mu2>
    <material>Gazebo/DarkGrey</material>
  </gazebo>
  <ros2_control name="mecanumdrive" type="system">
    <hardware>
      <plugin>gazebo_ros2_control/GazeboSystem</plugin>
    </hardware>
    <joint name="front_left_wheel_joint">
      <command_interface name="velocity"/>
      <state_interface name="position"/>
      <state_interface name="velocity"/>
    </joint>
    <joint name="rear_left_wheel_joint">
      <command_interface name="velocity"/>
      <state_interface name="position"/>
      <state_interface name="velocity"/>
    </joint>
    <joint name="rear_right_wheel_joint">
      <command_interface name="velocity"/>
      <state_interface name="position"/>
      <state_interface name="velocity"/>
    </joint>
    <joint name="front_right_wheel_joint">
      <command_interface name="velocity"/>
      <state_interface name="position"/>
      <state_interface name="velocity"/>
    </joint>
  </ros2_control>
  <ros2_control name="ros2_arm_control" type="system">
    <hardware>
      <plugin>gazebo_ros2_control/GazeboSystem</plugin>
    </hardware>
    <joint name="shoulder_pan_joint">
      <command_interface name="position"/>
      <state_interface name="position"/>
      <state_interface name="velocity"/>
    </joint>
    <joint name="shoulder_lift_joint">
      <command_interface name="position"/>
      <state_interface name="position">
        <param name="initial_value">-1.56</param>
      </state_interface>
      <state_interface name="velocity"/>
    </joint>
    <joint name="elbow_joint">
      <command_interface name="position"/>
      <state_interface name="position">
        <param name="initial_value">-1.56</param>
      </state_interface>
      <state_interface name="velocity"/>
    </joint>
    <joint name="wrist_joint">
      <command_interface name="position"/>
      <state_interface name="position">
        <param name="initial_value">1.56</param>
      </state_interface>
      <state_interface name="velocity"/>
    </joint>
  </ros2_control>
  <ros2_control name="ros2_gripper_control" type="system">
    <hardware>
      <plugin>gazebo_ros2_control/GazeboSystem</plugin>
    </hardware>
    <joint name="gripper_joint">
      <command_interface name="position"/>
      <state_interface name="position"/>
      <state_interface name="velocity"/>
    </joint>
    <joint name="_Gripper_joint_r">
      <param name="mimic">gripper_joint</param>
      <param name="multiplier">-1</param>
      <command_interface name="position"/>
      <state_interface name="position"/>
      <state_interface name="velocity"/>
    </joint>
    <joint name="_gripper_link_joint_l">
      <param name="mimic">gripper_joint</param>
      <param name="multiplier">-1.4</param>
      <command_interface name="position"/>
      <state_interface name="position"/>
      <state_interface name="velocity"/>
    </joint>
    <joint name="_gripper_link_joint_r">
      <param name="mimic">gripper_joint</param>
      <param name="multiplier">1.4</param>
      <command_interface name="position"/>
      <state_interface name="position"/>
      <state_interface name="velocity"/>
    </joint>
  </ros2_control>
  <gazebo>
    <plugin filename="libgazebo_ros2_control.so" name="gazebo_ros2_control">
      <parameters>/home/balaji/ro47007_mirte_ws/install/share/mirte_base_control/config/mirte_base_control.yaml</parameters>
      <parameters>/home/balaji/ro47007_mirte_ws/install/share/mirte_master_arm_control/config/mirte_master_arm_control.yaml</parameters>
    </plugin>
    <plugin filename="libgazebo_ros_planar_move.so" name="gazebo_planar_move">
      <robot_base_frame>base_link</robot_base_frame>
    </plugin>
    <plugin filename="libgazebo_ros_p3d.so" name="libgazebo_ros_p3d">
      <ros>
        <namespace>groundtruth</namespace>
        <remapping>odom:=odom</remapping>
      </ros>
      <frame_name>world</frame_name>
      <body_name>base_link</body_name>
      <update_rate>200.0</update_rate>
      <gaussian_noise>0.0</gaussian_noise>
    </plugin>
  </gazebo>
  <link name="base_link"/>
  <gazebo reference="base_link">
    <kinematic>1</kinematic>
  </gazebo>
  <joint name="frame_base_joint" type="fixed">
    <origin rpy="0 0 1.5707963267948966" xyz="0 0 0.10"/>
    <parent link="base_link"/>
    <child link="frame_link"/>
  </joint>
  <link name="frame_link">
    <inertial>
      <origin xyz="-0.00024285 0.0082178 -0.0437661"/>
      <mass value="5.0"/>
      <inertia ixx="0.03416666666666667" ixy="0" ixz="0" iyy="0.016541666666666666" iyz="0" izz="0.047708333333333346"/>
    </inertial>
    <visual>
      <geometry>
        <mesh filename="meshes/frame_link.STL"/>
      </geometry>
      <material name="">
        <color rgba="0.52941 0.54902 0.54902 1"/>
      </material>
    </visual>
    <collision>
      <origin xyz="0 0 -0.03"/>
      <geometry>
        <box size="0.19 0.28 0.06"/>
      </geometry>
    </collision>
    <collision>
      <origin xyz="0 0.05 0.045"/>
      <geometry>
        <box size="0.18 0.16 0.05"/>
      </geometry>
    </collision>
    <collision>
      <origin rpy="0 0 0.5672320068981571" xyz="-0.062156 -0.002558 0.0125"/>
      <geometry>
        <box size="0.013 0.03 0.025"/>
      </geometry>
    </collision>
    <collision>
      <origin rpy="0 0 -0.5672320068981571" xyz="0.064835 0.001664 0.0125"/>
      <geometry>
        <box size="0.013 0.04 0.025"/>
      </geometry>
    </collision>
  </link>
  <!-- 0.025   -1 -->
  <link name="front_left_wheel">
    <inertial>
      <origin xyz="0 0 0.025"/>
      <mass value="2.15"/>
      <inertia ixx="0.0018857291666666668" ixy="0" ixz="0" iyy="0.0018857291666666668" iyz="0" izz="0.0026875000000000002"/>
    </inertial>
    <visual>
      <geometry>
        <mesh filename="meshes/wheel_left.STL"/>
      </geometry>
      <material name="">
        <color rgba="0.79216 0.81961 0.93333 1"/>
      </material>
    </visual>
    <collision>
      <origin xyz="0 0 0.025"/>
      <geometry>
        <cylinder length="0.055" radius="0.05"/>
      </geometry>
    </collision>
  </link>
  <joint name="front_left_wheel_joint" type="continuous">
    <origin rpy="1.5708 0 -1.5708" xyz="0.153 -0.085 -0.0455"/>
    <parent link="frame_link"/>
    <child link="front_left_wheel"/>
    <axis xyz="0 0 -1"/>
  </joint>
  <transmission name="front_left_wheel_transmission">
    <type>transmission_interface/SimpleTransmission</type>
    <joint name="front_left_wheel_joint">
      <hardwareInterface>hardware_interface/VelocityJointInterface</hardwareInterface>
    </joint>
    <actuator name="front_left_wheel_actuator">
      <mechanicalReduction>1</mechanicalReduction>
    </actuator>
  </transmission>
  <link name="rear_left_wheel">
    <inertial>
      <origin xyz="0 0 0.025"/>
      <mass value="2.15"/>
      <inertia ixx="0.0018857291666666668" ixy="0" ixz="0" iyy="0.0018857291666666668" iyz="0" izz="0.0026875000000000002"/>
    </inertial>
    <visual>
      <geometry>
        <mesh filename="meshes/wheel_right.STL"/>
      </geometry>
      <material name="">
        <color rgba="0.79216 0.81961 0.93333 1"/>
      </material>
    </visual>
    <collision>
      <origin xyz="0 0 0.025"/>
      <geometry>
        <cylinder length="0.055" radius="0.05"/>
      </geometry>
    </collision>
  </link>
  <joint name="rear_left_wheel_joint" type="continuous">
    <origin rpy="1.5708 0 -1.5708" xyz="0.153 0.085 -0.0455"/>
    <parent link="frame_link"/>
    <child link="rear_left_wheel"/>
    <axis xyz="0 0 -1"/>
  </joint>
  <transmission name="rear_left_wheel_transmission">
    <type>transmission_interface/SimpleTransmission</type>
    <joint name="rear_left_wheel_joint">
      <hardwareInterface>hardware_interface/VelocityJointInterface</hardwareInterface>
    </joint>
    <actuator name="rear_left_wheel_actuator">
      <mechanicalReduction>1</mechanicalReduction>
    </actuator>
  </transmission>
  <link name="front_right_wheel">
    <inertial>
      <origin xyz="0 0 -0.025"/>
      <mass value="2.15"/>
      <inertia ixx="0.0018857291666666668" ixy="0" ixz="0" iyy="0.0018857291666666668" iyz="0" izz="0.0026875000000000002"/>
    </inertial>
    <visual>
      <geometry>
        <mesh filename="meshes/wheel_right.STL"/>
      </geometry>
      <material name="">
        <color rgba="0.79216 0.81961 0.93333 1"/>
      </material>
    </visual>
    <collision>
      <origin xyz="0 0 -0.025"/>
      <geometry>
        <cylinder length="0.055" radius="0.05"/>
      </geometry>
    </collision>
  </link>
  <joint name="front_right_wheel_joint" type="continuous">
    <origin rpy="1.5708 0 -1.5708" xyz="-0.098 -0.085 -0.0455"/>
    <parent link="frame_link"/>
    <child link="front_right_wheel"/>
    <axis xyz="0 0 -1"/>
  </joint>
  <transmission name="front_right_wheel_transmission">
    <type>transmission_interface/SimpleTransmission</type>
    <joint name="front_right_wheel_joint">
      <hardwareInterface>hardware_interface/VelocityJointInterface</hardwareInterface>
    </joint>
    <actuator name="front_right_wheel_actuator">
      <mechanicalReduction>1</mechanicalReduction>
    </actuator>
  </transmission>
  <link name="rear_right_wheel">
    <inertial>
      <origin xyz="0 0 -0.025"/>
      <mass value="2.15"/>
      <inertia ixx="0.0018857291666666668" ixy="0" ixz="0" iyy="0.0018857291666666668" iyz="0" izz="0.0026875000000000002"/>
    </inertial>
    <visual>
      <geometry>
        <mesh filename="meshes/wheel_left.STL"/>
      </geometry>
      <material name="">
        <color rgba="0.79216 0.81961 0.93333 1"/>
      </material>
    </visual>
    <collision>
      <origin xyz="0 0 -0.025"/>
      <geometry>
        <cylinder length="0.055" radius="0.05"/>
      </geometry>
    </collision>
  </link>
  <joint name="rear_right_wheel_joint" type="continuous">
    <origin rpy="1.5708 0 -1.5708" xyz="-0.098 0.085 -0.0455"/>
    <parent link="frame_link"/>
    <child link="rear_right_wheel"/>
    <axis xyz="0 0 -1"/>
  </joint>
  <transmission name="rear_right_wheel_transmission">
    <type>transmission_interface/SimpleTransmission</type>
    <joint name="rear_right_wheel_joint">
      <hardwareInterface>hardware_interface/VelocityJointInterface</hardwareInterface>
    </joint>
    <actuator name="rear_right_wheel_actuator">
      <mechanicalReduction>1</mechanicalReduction>
    </actuator>
  </transmission>
  <link name="shoulder_pan">
    <inertial>
      <origin rpy="0 0 0" xyz="-1.27894101951934E-05 0.0208058767653727 0.00585680210359747"/>
      <mass value="0.0689676051678483"/>
      <inertia ixx="1.10736817655159E-05" ixy="-9.06572517495388E-09" ixz="-2.13237951815141E-10" iyy="2.24480121987499E-05" iyz="-4.10984989642458E-07" izz="1.70252517510809E-05"/>
    </inertial>
    <visual>
      <origin rpy="0 0 0" xyz="0 0 0"/>
      <geometry>
        <mesh filename="meshes/arm_Rot.STL"/>
      </geometry>
      <material name="">
        <color rgba="0.792156862745098 0.819607843137255 0.933333333333333 1"/>
      </material>
    </visual>
    <collision>
      <origin rpy="0 0 0" xyz="0 0 0"/>
      <geometry>
        <mesh filename="meshes/arm_Rot.STL"/>
      </geometry>
    </collision>
  </link>
  <joint name="shoulder_pan_joint" type="revolute">
    <origin rpy="1.5708 0 3.1416" xyz="0 -0.079274 0.06"/>
    <parent link="frame_link"/>
    <child link="shoulder_pan"/>
    <axis xyz="0 1 0"/>
    <limit effort="2.0" lower="-1.5707963267948966" upper="1.5707963267948966" velocity="2.0"/>
  </joint>
  <link name="shoulder_lift">
    <inertial>
      <origin rpy="0 0 0" xyz="0.0764974362945755 0.000442680770353329 -4.93690401059954E-09"/>
      <mass value="0.104616018825837"/>
      <inertia ixx="3.85677839717214E-05" ixy="1.84827309047044E-08" ixz="1.42612941509626E-12" iyy="2.54245117502168E-05" iyz="-2.05142765424474E-12" izz="5.51611966703411E-05"/>
    </inertial>
    <visual>
      <origin rpy="0 0 0" xyz="0 0 0"/>
      <geometry>
        <mesh filename="meshes/arm_Shoulder.STL"/>
      </geometry>
      <material name="">
        <color rgba="0.501960784313725 0.501960784313725 0.501960784313725 1"/>
      </material>
    </visual>
    <collision>
      <origin rpy="0 0 0" xyz="0 0 0"/>
      <geometry>
        <mesh filename="meshes/arm_Shoulder.STL"/>
      </geometry>
    </collision>
  </link>
  <joint name="shoulder_lift_joint" type="revolute">
    <origin rpy="3.1416 0 1.5708" xyz="0 0.0281 -0.00625"/>
    <parent link="shoulder_pan"/>
    <child link="shoulder_lift"/>
    <axis xyz="0 1 0"/>
    <limit effort="2.0" lower="-1.5707963267948966" upper="1.5707963267948966" velocity="2.0"/>
  </joint>
  <link name="elbow">
    <inertial>
      <origin rpy="0 0 0" xyz="0.000768647609078278 0.0642294520091309 -2.34835863116567E-08"/>
      <mass value="0.0709795960901316"/>
      <inertia ixx="2.06491501981418E-05" ixy="1.76077623308388E-08" ixz="-6.06300089698489E-13" iyy="2.45686930201746E-05" iyz="3.04033870141042E-12" izz="3.79131240892547E-05"/>
    </inertial>
    <visual>
      <origin rpy="0 0 0" xyz="0 0 0"/>
      <geometry>
        <mesh filename="meshes/arm_Elbow.STL"/>
      </geometry>
      <material name="">
        <color rgba="0.501960784313725 0.501960784313725 0.501960784313725 1"/>
      </material>
    </visual>
    <collision>
      <origin rpy="0 0 0" xyz="0 0 0"/>
      <geometry>
        <mesh filename="meshes/arm_Elbow.STL"/>
      </geometry>
    </collision>
  </link>
  <joint name="elbow_joint" type="revolute">
    <origin rpy="-3.1416 0 1.5708" xyz="0.1378 0 0"/>
    <parent link="shoulder_lift"/>
    <child link="elbow"/>
    <axis xyz="1 0 0"/>
    <limit effort="2.0" lower="-1.5707963267948966" upper="1.5707963267948966" velocity="2.0"/>
  </joint>
  <link name="wrist">
    <inertial>
      <origin rpy="0 0 0" xyz="0.0225315136140379 0.000488092971965825 -2.74405760168628E-06"/>
      <mass value="0.0464803878756425"/>
      <inertia ixx="1.36228105923869E-05" ixy="-2.7486243117372E-08" ixz="-2.82180089490711E-08" iyy="7.22412070962973E-06" iyz="3.4652740053439E-09" izz="1.75204377049058E-05"/>
    </inertial>
    <visual>
      <origin rpy="0 0 0" xyz="0 0 0"/>
      <geometry>
        <mesh filename="meshes/arm_Wrist.STL"/>
      </geometry>
      <material name="">
        <color rgba="0.501960784313725 0.501960784313725 0.501960784313725 1"/>
      </material>
    </visual>
    <collision>
      <origin rpy="0 0 0" xyz="0 0 0"/>
      <geometry>
        <mesh filename="meshes/arm_Wrist.STL"/>
      </geometry>
    </collision>
  </link>
  <joint name="wrist_joint" type="revolute">
    <origin rpy="3.1416 0 1.5708" xyz="-0.00014 0.14265 0"/>
    <parent link="elbow"/>
    <child link="wrist"/>
    <axis xyz="0 1 0"/>
    <limit effort="2.0" lower="-1.5707963267948966" upper="1.5707963267948966" velocity="2.0"/>
  </joint>
  <link name="gripper">
    <inertial>
      <origin rpy="0 0 0" xyz="0.0128439388984141 0.00467107677719844 -0.023531822516204"/>
      <mass value="0.0109603788959771"/>
      <inertia ixx="1.64287457972505E-06" ixy="-2.54915969005551E-10" ixz="-3.17766452649769E-07" iyy="2.96639543247368E-06" iyz="-7.8877045337556E-08" izz="1.49193844890504E-06"/>
    </inertial>
    <visual>
      <origin rpy="0 0 0" xyz="0 0 0"/>
      <geometry>
        <mesh filename="meshes/Gripper.STL"/>
      </geometry>
      <material name="">
        <color rgba="0.792156862745098 0.819607843137255 0.933333333333333 1"/>
      </material>
    </visual>
    <collision>
      <origin rpy="0 0 0" xyz="0 0 0"/>
      <geometry>
        <mesh filename="meshes/Gripper.STL"/>
      </geometry>
    </collision>
  </link>
  <joint name="gripper_joint" type="revolute">
    <origin rpy="-1.5708 0 0" xyz="0.0435 -0.012 0.0045"/>
    <parent link="wrist"/>
    <child link="gripper"/>
    <axis xyz="0 -1 0"/>
    <limit effort="2.0" lower="-.20" upper="0.25" velocity="2.0"/>
  </joint>
  <link name="_gripper_link_r">
    <inertial>
      <origin rpy="0 0 0" xyz="-1.28017477174502E-08 0.00327806945611438 -0.015628977594268"/>
      <mass value="0.00257857268754656"/>
      <inertia ixx="4.78055533789155E-07" ixy="-5.230783542464E-14" ixz="-2.66258471113313E-13" iyy="4.85504704619794E-07" iyz="-3.012555423281E-08" izz="3.42900323604584E-08"/>
    </inertial>
    <visual>
      <origin rpy="0 0 0" xyz="0 0 0"/>
      <geometry>
        <mesh filename="meshes/_gripper_link_r.STL"/>
      </geometry>
      <material name="">
        <color rgba="0.792156862745098 0.819607843137255 0.933333333333333 1"/>
      </material>
    </visual>
    <collision>
      <origin rpy="0 0 0" xyz="0 0 0"/>
      <geometry>
        <mesh filename="meshes/_gripper_link_r.STL"/>
      </geometry>
    </collision>
  </link>
  <joint name="_gripper_link_joint_r" type="revolute">
    <origin rpy="1.5708 0 -1.3641" xyz="0.0605 0.0205 -0.0055"/>
    <parent link="wrist"/>
    <child link="_gripper_link_r"/>
    <axis xyz="0 -1 0"/>
    <limit effort="0.0" lower="-3.14" upper="3.14" velocity="0.0"/>
    <mimic joint="gripper_joint" multiplier="1.4"/>
  </joint>
  <link name="gripper_finger_r">
    <inertial>
      <origin rpy="0 0 0" xyz="0.0053582194655247 0.00456985538673528 -0.0146658643393019"/>
      <mass value="0.00531205810762776"/>
      <inertia ixx="6.56191216382328E-07" ixy="4.9417968242523E-09" ixz="-1.23756532787867E-07" iyy="7.67327744037516E-07" iyz="3.35637410041389E-08" izz="1.97644006824673E-07"/>
    </inertial>
    <visual>
      <origin rpy="0 0 0" xyz="0 0 0"/>
      <geometry>
        <mesh filename="meshes/gripper_finger_r.STL"/>
      </geometry>
      <material name="">
        <color rgba="0.792156862745098 0.819607843137255 0.933333333333333 1"/>
      </material>
    </visual>
    <collision>
      <origin rpy="0 0 0" xyz="0 0 0"/>
      <geometry>
        <mesh filename="meshes/gripper_finger_r.STL"/>
      </geometry>
    </collision>
  </link>
  <joint name="gripper_finger_joint_r" type="fixed">
    <origin rpy="0 0.20667 3.1416" xyz="0 0.01 -0.037"/>
    <parent link="_gripper_link_r"/>
    <child link="gripper_finger_r"/>
    <axis xyz="0 0 1"/>
  </joint>
  <link name="_gripper_link_l">
    <inertial>
      <origin rpy="0 0 0" xyz="-2.05686406795635E-09 0.00327805387383495 -0.0156289677422455"/>
      <mass value="0.0025785751096632"/>
      <inertia ixx="4.78055731035803E-07" ixy="1.11114248069431E-14" ixz="5.45978048241403E-14" iyy="4.85504889003676E-07" iyz="-3.01256260104972E-08" izz="3.4290092499709E-08"/>
    </inertial>
    <visual>
      <origin rpy="0 0 0" xyz="0 0 0"/>
      <geometry>
        <mesh filename="meshes/_gripper_link_l.STL"/>
      </geometry>
      <material name="">
        <color rgba="0.792156862745098 0.819607843137255 0.933333333333333 1"/>
      </material>
    </visual>
    <collision>
      <origin rpy="0 0 0" xyz="0 0 0"/>
      <geometry>
        <mesh filename="meshes/_gripper_link_l.STL"/>
      </geometry>
    </collision>
  </link>
  <joint name="_gripper_link_joint_l" type="revolute">
    <origin rpy="1.5708 0 -1.7775" xyz="0.0605 -0.0205 -0.0055"/>
    <parent link="wrist"/>
    <child link="_gripper_link_l"/>
    <axis xyz="0 -1 0"/>
    <limit effort="0.0" lower="-3.14" upper="3.14" velocity="0.0"/>
    <mimic joint="gripper_joint" multiplier="-1.4"/>
  </joint>
  <link name="gripper_finger_l">
    <inertial>
      <origin rpy="0 0 0" xyz="0.00535821399237165 0.00543015238565805 -0.0146658496889369"/>
      <mass value="0.00531205810762777"/>
      <inertia ixx="6.56191216382329E-07" ixy="-4.94179682425222E-09" ixz="-1.23756532787868E-07" iyy="7.67327744037519E-07" iyz="-3.35637410041387E-08" izz="1.97644006824674E-07"/>
    </inertial>
    <visual>
      <origin rpy="0 0 0" xyz="0 0 0"/>
      <geometry>
        <mesh filename="meshes/gripper_finger_l.STL"/>
      </geometry>
      <material name="">
        <color rgba="0.792156862745098 0.819607843137255 0.933333333333333 1"/>
      </material>
    </visual>
    <collision>
      <origin rpy="0 0 0" xyz="0 0 0"/>
      <geometry>
        <mesh filename="meshes/gripper_finger_l.STL"/>
      </geometry>
    </collision>
  </link>
  <joint name="gripper_finger_joint_l" type="fixed">
    <origin rpy="0 0.20667 0" xyz="0 0 -0.037"/>
    <parent link="_gripper_link_l"/>
    <child link="gripper_finger_l"/>
    <axis xyz="0 0 1"/>
  </joint>
  <link name="_Gripper_r">
    <inertial>
      <origin rpy="0 0 0" xyz="-0.011058953981311 0.00572378908343621 -0.0203029402870159"/>
      <mass value="0.0127576574866818"/>
      <inertia ixx="1.91784274511554E-06" ixy="-2.13316668505462E-10" ixz="3.18097729104346E-07" iyy="3.19294602407598E-06" iyz="-1.86219200901589E-07" izz="1.63755141963222E-06"/>
    </inertial>
    <visual>
      <origin rpy="0 0 0" xyz="0 0 0"/>
      <geometry>
        <mesh filename="meshes/_Gripper_r.STL"/>
      </geometry>
      <material name="">
        <color rgba="0.792156862745098 0.819607843137255 0.933333333333333 1"/>
      </material>
    </visual>
    <collision>
      <origin rpy="0 0 0" xyz="0 0 0"/>
      <geometry>
        <mesh filename="meshes/_Gripper_r.STL"/>
      </geometry>
    </collision>
  </link>
  <joint name="_Gripper_joint_r" type="revolute">
    <origin rpy="-1.5708 0 -3.1416" xyz="0.0435 0.012 0.0045"/>
    <parent link="wrist"/>
    <child link="_Gripper_r"/>
    <axis xyz="0 -1 0"/>
    <limit effort="2.0" lower="-.25" upper="0.20" velocity="2.0"/>
    <mimic joint="gripper_joint" multiplier="-1"/>
  </joint>
  <gazebo>
    <plugin filename="libgazebo_grasp_fix.so" name="gazebo_grasp_fix">
      <arm>
        <arm_name>finger_gripper</arm_name>
        <palm_link>wrist</palm_link>
        <gripper_link>gripper</gripper_link>
        <gripper_link>_Gripper_r</gripper_link>
        <gripper_link>_gripper_link_l</gripper_link>
        <gripper_link>gripper_finger_l</gripper_link>
        <gripper_link>_gripper_link_r</gripper_link>
        <gripper_link>gripper_finger_r</gripper_link>
      </arm>
      <forces_angle_tolerance>100</forces_angle_tolerance>
      <update_rate>4</update_rate>
      <grip_count_threshold>4</grip_count_threshold>
      <max_grip_count>8</max_grip_count>
      <release_tolerance>0.005</release_tolerance>
      <disable_collisions_on_attach>false</disable_collisions_on_attach>
    </plugin>
  </gazebo>
</robot>
